2025-07-19 01:27:58,813 [INFO] app:99 <module> - [32mDB ¦¨¥\±Ò°Ê[0m
2025-07-19 01:27:59,786 [INFO] _internal:97 _log - [32m[31m[1mWARNING: This is a development server. Do not use it in a production deployment. Use a production WSGI server instead.[0m
 * Running on all addresses (0.0.0.0)
 * Running on http://127.0.0.1:5050
 * Running on http://192.168.1.192:5050[0m
2025-07-19 01:27:59,788 [INFO] _internal:97 _log - [32m[33mPress CTRL+C to quit[0m[0m
2025-07-19 01:31:27,457 [DEBUG] models:377 log_response_time - [97m[GET] /announcements took 0.005 seconds[0m
2025-07-19 01:31:27,460 [INFO] _internal:97 _log - [32m127.0.0.1 - - [19/Jul/2025 01:31:27] "[33mGET /announcements HTTP/1.1[0m" 404 -[0m
2025-07-19 01:31:42,657 [DEBUG] models:377 log_response_time - [97m[GET] /api/announcements took 0.001 seconds[0m
2025-07-19 01:31:42,661 [INFO] _internal:97 _log - [32m127.0.0.1 - - [19/Jul/2025 01:31:42] "[33mGET /api/announcements HTTP/1.1[0m" 404 -[0m
2025-07-19 01:31:50,421 [DEBUG] models:377 log_response_time - [97m[GET] /api/announcements took 0.002 seconds[0m
2025-07-19 01:31:50,422 [INFO] _internal:97 _log - [32m127.0.0.1 - - [19/Jul/2025 01:31:50] "[33mGET /api/announcements HTTP/1.1[0m" 404 -[0m
2025-07-19 01:32:14,450 [DEBUG] models:377 log_response_time - [97m[GET] /announcements took 0.001 seconds[0m
2025-07-19 01:32:14,452 [INFO] _internal:97 _log - [32m127.0.0.1 - - [19/Jul/2025 01:32:14] "[33mGET /announcements HTTP/1.1[0m" 404 -[0m
2025-07-19 01:32:47,670 [INFO] app:100 <module> - [32mDB ¦¨¥\±Ò°Ê[0m
2025-07-19 01:32:48,643 [INFO] _internal:97 _log - [32m[31m[1mWARNING: This is a development server. Do not use it in a production deployment. Use a production WSGI server instead.[0m
 * Running on all addresses (0.0.0.0)
 * Running on http://127.0.0.1:5050
 * Running on http://192.168.1.192:5050[0m
2025-07-19 01:32:48,645 [INFO] _internal:97 _log - [32m[33mPress CTRL+C to quit[0m[0m
2025-07-19 01:32:50,429 [DEBUG] models:377 log_response_time - [97m[GET] /announcements took 0.004 seconds[0m
2025-07-19 01:32:50,431 [INFO] _internal:97 _log - [32m127.0.0.1 - - [19/Jul/2025 01:32:50] "GET /announcements HTTP/1.1" 200 -[0m
2025-07-19 01:33:23,507 [DEBUG] models:377 log_response_time - [97m[GET] /api/doc took 0.104 seconds[0m
2025-07-19 01:33:23,508 [INFO] _internal:97 _log - [32m127.0.0.1 - - [19/Jul/2025 01:33:23] "GET /api/doc HTTP/1.1" 200 -[0m
2025-07-19 01:33:23,583 [DEBUG] models:377 log_response_time - [97m[GET] /swaggerui/droid-sans.css took 0.047 seconds[0m
2025-07-19 01:33:23,584 [INFO] _internal:97 _log - [32m127.0.0.1 - - [19/Jul/2025 01:33:23] "GET /swaggerui/droid-sans.css HTTP/1.1" 200 -[0m
2025-07-19 01:33:23,666 [DEBUG] models:377 log_response_time - [97m[GET] /swaggerui/swagger-ui.css took 0.019 seconds[0m
2025-07-19 01:33:23,667 [INFO] _internal:97 _log - [32m127.0.0.1 - - [19/Jul/2025 01:33:23] "GET /swaggerui/swagger-ui.css HTTP/1.1" 200 -[0m
2025-07-19 01:33:23,869 [DEBUG] models:377 log_response_time - [97m[GET] /swaggerui/swagger-ui-bundle.js took 0.025 seconds[0m
2025-07-19 01:33:23,870 [INFO] _internal:97 _log - [32m127.0.0.1 - - [19/Jul/2025 01:33:23] "GET /swaggerui/swagger-ui-bundle.js HTTP/1.1" 200 -[0m
2025-07-19 01:33:23,908 [DEBUG] models:377 log_response_time - [97m[GET] /swaggerui/swagger-ui-standalone-preset.js took 0.064 seconds[0m
2025-07-19 01:33:23,909 [INFO] _internal:97 _log - [32m127.0.0.1 - - [19/Jul/2025 01:33:23] "GET /swaggerui/swagger-ui-standalone-preset.js HTTP/1.1" 200 -[0m
2025-07-19 01:33:24,285 [DEBUG] models:377 log_response_time - [97m[GET] /swagger.json took 0.007 seconds[0m
2025-07-19 01:33:24,286 [INFO] _internal:97 _log - [32m127.0.0.1 - - [19/Jul/2025 01:33:24] "GET /swagger.json HTTP/1.1" 200 -[0m
2025-07-19 01:33:24,287 [DEBUG] models:377 log_response_time - [97m[GET] /swaggerui/favicon-32x32.png took 0.001 seconds[0m
2025-07-19 01:33:24,290 [INFO] _internal:97 _log - [32m127.0.0.1 - - [19/Jul/2025 01:33:24] "GET /swaggerui/favicon-32x32.png HTTP/1.1" 200 -[0m
2025-07-19 01:40:58,699 [ERROR] util:25 wrapper - [91mBad Request: 400 Bad Request: The browser (or proxy) sent a request that this server could not understand.[0m
2025-07-19 01:40:58,700 [DEBUG] models:377 log_response_time - [97m[POST] /announcements took 0.008 seconds[0m
2025-07-19 01:40:58,701 [INFO] _internal:97 _log - [32m127.0.0.1 - - [19/Jul/2025 01:40:58] "[31m[1mPOST /announcements HTTP/1.1[0m" 400 -[0m
2025-07-19 01:41:14,178 [INFO] app:100 <module> - [32mDB ¦¨¥\±Ò°Ê[0m
2025-07-19 01:41:15,160 [INFO] _internal:97 _log - [32m[31m[1mWARNING: This is a development server. Do not use it in a production deployment. Use a production WSGI server instead.[0m
 * Running on all addresses (0.0.0.0)
 * Running on http://127.0.0.1:5050
 * Running on http://192.168.1.192:5050[0m
2025-07-19 01:41:15,162 [INFO] _internal:97 _log - [32m[33mPress CTRL+C to quit[0m[0m
2025-07-19 01:41:16,641 [ERROR] util:25 wrapper - [91mBad Request: 400 Bad Request: The browser (or proxy) sent a request that this server could not understand.[0m
2025-07-19 01:41:16,642 [DEBUG] models:377 log_response_time - [97m[POST] /announcements took 0.005 seconds[0m
2025-07-19 01:41:16,644 [INFO] _internal:97 _log - [32m127.0.0.1 - - [19/Jul/2025 01:41:16] "[31m[1mPOST /announcements HTTP/1.1[0m" 400 -[0m
2025-07-19 01:45:17,733 [INFO] app:100 <module> - [32mDB ¦¨¥\±Ò°Ê[0m
2025-07-19 01:45:18,702 [INFO] _internal:97 _log - [32m[31m[1mWARNING: This is a development server. Do not use it in a production deployment. Use a production WSGI server instead.[0m
 * Running on all addresses (0.0.0.0)
 * Running on http://127.0.0.1:5050
 * Running on http://192.168.1.192:5050[0m
2025-07-19 01:45:18,703 [INFO] _internal:97 _log - [32m[33mPress CTRL+C to quit[0m[0m
2025-07-19 01:45:20,460 [ERROR] util:35 wrapper - [91mAn error occurred: AttributeError: 'Request' object has no attribute 'payload'[0m
2025-07-19 01:45:20,462 [ERROR] app:875 log_exception - [91mException on /announcements [POST][0m
Traceback (most recent call last):
  File "E:\Smitlea_project\·s¼W\HsinyuOS_test\static\util.py", line 22, in wrapper
    return func(*args, **kwargs)
  File "E:\Smitlea_project\·s¼W\HsinyuOS_test\function\hr.py", line 58, in post
    data = request.payload
AttributeError: 'Request' object has no attribute 'payload'

During handling of the above exception, another exception occurred:

Traceback (most recent call last):
  File "C:\Users\allen\.virtualenvs\·s¼W-wo_VgXtn\lib\site-packages\flask\app.py", line 917, in full_dispatch_request
    rv = self.dispatch_request()
  File "C:\Users\allen\.virtualenvs\·s¼W-wo_VgXtn\lib\site-packages\flask\app.py", line 902, in dispatch_request
    return self.ensure_sync(self.view_functions[rule.endpoint])(**view_args)  # type: ignore[no-any-return]
  File "C:\Users\allen\.virtualenvs\·s¼W-wo_VgXtn\lib\site-packages\flask_restx\api.py", line 402, in wrapper
    resp = resource(*args, **kwargs)
  File "C:\Users\allen\.virtualenvs\·s¼W-wo_VgXtn\lib\site-packages\flask\views.py", line 110, in view
    return current_app.ensure_sync(self.dispatch_request)(**kwargs)  # type: ignore[no-any-return]
  File "C:\Users\allen\.virtualenvs\·s¼W-wo_VgXtn\lib\site-packages\flask_restx\resource.py", line 41, in dispatch_request
    resp = meth(*args, **kwargs)
  File "C:\Users\allen\.virtualenvs\·s¼W-wo_VgXtn\lib\site-packages\flask_jwt_extended\view_decorators.py", line 170, in decorator
    return current_app.ensure_sync(fn)(*args, **kwargs)
  File "E:\Smitlea_project\·s¼W\HsinyuOS_test\static\util.py", line 36, in wrapper
    return abort(
  File "C:\Users\allen\.virtualenvs\·s¼W-wo_VgXtn\lib\site-packages\flask_restx\errors.py", line 28, in abort
    flask.abort(code)
  File "C:\Users\allen\.virtualenvs\·s¼W-wo_VgXtn\lib\site-packages\flask\helpers.py", line 284, in abort
    current_app.aborter(code, *args, **kwargs)
  File "C:\Users\allen\.virtualenvs\·s¼W-wo_VgXtn\lib\site-packages\werkzeug\exceptions.py", line 876, in __call__
    raise self.mapping[code](*args, **kwargs)
werkzeug.exceptions.InternalServerError: 500 Internal Server Error: The server encountered an internal error and was unable to complete your request. Either the server is overloaded or there is an error in the application.
2025-07-19 01:45:20,477 [DEBUG] models:377 log_response_time - [97m[POST] /announcements took 0.021 seconds[0m
2025-07-19 01:45:20,479 [INFO] _internal:97 _log - [32m127.0.0.1 - - [19/Jul/2025 01:45:20] "[35m[1mPOST /announcements HTTP/1.1[0m" 500 -[0m
2025-07-19 01:46:00,480 [INFO] app:100 <module> - [32mDB ¦¨¥\±Ò°Ê[0m
2025-07-19 01:46:01,612 [INFO] _internal:97 _log - [32m[31m[1mWARNING: This is a development server. Do not use it in a production deployment. Use a production WSGI server instead.[0m
 * Running on all addresses (0.0.0.0)
 * Running on http://127.0.0.1:5050
 * Running on http://192.168.1.192:5050[0m
2025-07-19 01:46:01,613 [INFO] _internal:97 _log - [32m[33mPress CTRL+C to quit[0m[0m
2025-07-19 01:46:03,661 [ERROR] util:25 wrapper - [91mBad Request: 400 Bad Request: The browser (or proxy) sent a request that this server could not understand.[0m
2025-07-19 01:46:03,662 [DEBUG] models:377 log_response_time - [97m[POST] /announcements took 0.007 seconds[0m
2025-07-19 01:46:03,664 [INFO] _internal:97 _log - [32m127.0.0.1 - - [19/Jul/2025 01:46:03] "[31m[1mPOST /announcements HTTP/1.1[0m" 400 -[0m
2025-07-19 01:46:06,623 [ERROR] util:25 wrapper - [91mBad Request: 400 Bad Request: The browser (or proxy) sent a request that this server could not understand.[0m
2025-07-19 01:46:06,624 [DEBUG] models:377 log_response_time - [97m[POST] /announcements took 0.003 seconds[0m
2025-07-19 01:46:06,625 [INFO] _internal:97 _log - [32m127.0.0.1 - - [19/Jul/2025 01:46:06] "[31m[1mPOST /announcements HTTP/1.1[0m" 400 -[0m
2025-07-19 01:46:57,779 [DEBUG] models:377 log_response_time - [97m[POST] /announcements took 0.010 seconds[0m
2025-07-19 01:46:57,781 [INFO] _internal:97 _log - [32m127.0.0.1 - - [19/Jul/2025 01:46:57] "[35m[1mPOST /announcements HTTP/1.1[0m" 201 -[0m
2025-07-19 01:49:01,379 [DEBUG] models:377 log_response_time - [97m[GET] /announcements took 0.003 seconds[0m
2025-07-19 01:49:01,380 [INFO] _internal:97 _log - [32m127.0.0.1 - - [19/Jul/2025 01:49:01] "GET /announcements HTTP/1.1" 200 -[0m
2025-07-19 01:54:43,765 [INFO] app:100 <module> - [32mDB ¦¨¥\±Ò°Ê[0m
2025-07-19 01:54:44,731 [INFO] _internal:97 _log - [32m[31m[1mWARNING: This is a development server. Do not use it in a production deployment. Use a production WSGI server instead.[0m
 * Running on all addresses (0.0.0.0)
 * Running on http://127.0.0.1:5050
 * Running on http://192.168.1.192:5050[0m
2025-07-19 01:54:44,734 [INFO] _internal:97 _log - [32m[33mPress CTRL+C to quit[0m[0m
2025-07-19 01:54:48,239 [ERROR] util:35 wrapper - [91mAn error occurred: AttributeError: 'NoneType' object has no attribute 'isoformat'[0m
2025-07-19 01:54:48,241 [ERROR] app:875 log_exception - [91mException on /announcements [GET][0m
Traceback (most recent call last):
  File "E:\Smitlea_project\·s¼W\HsinyuOS_test\static\util.py", line 22, in wrapper
    return func(*args, **kwargs)
  File "E:\Smitlea_project\·s¼W\HsinyuOS_test\function\hr.py", line 48, in get
    return {"status": "0", "result": [a.to_dict() for a in rows]}, 200
  File "E:\Smitlea_project\·s¼W\HsinyuOS_test\function\hr.py", line 48, in <listcomp>
    return {"status": "0", "result": [a.to_dict() for a in rows]}, 200
  File "E:\Smitlea_project\·s¼W\HsinyuOS_test\static\models.py", line 403, in to_dict
    "record_date": self.record_date.isoformat(),
AttributeError: 'NoneType' object has no attribute 'isoformat'

During handling of the above exception, another exception occurred:

Traceback (most recent call last):
  File "C:\Users\allen\.virtualenvs\·s¼W-wo_VgXtn\lib\site-packages\flask\app.py", line 917, in full_dispatch_request
    rv = self.dispatch_request()
  File "C:\Users\allen\.virtualenvs\·s¼W-wo_VgXtn\lib\site-packages\flask\app.py", line 902, in dispatch_request
    return self.ensure_sync(self.view_functions[rule.endpoint])(**view_args)  # type: ignore[no-any-return]
  File "C:\Users\allen\.virtualenvs\·s¼W-wo_VgXtn\lib\site-packages\flask_restx\api.py", line 402, in wrapper
    resp = resource(*args, **kwargs)
  File "C:\Users\allen\.virtualenvs\·s¼W-wo_VgXtn\lib\site-packages\flask\views.py", line 110, in view
    return current_app.ensure_sync(self.dispatch_request)(**kwargs)  # type: ignore[no-any-return]
  File "C:\Users\allen\.virtualenvs\·s¼W-wo_VgXtn\lib\site-packages\flask_restx\resource.py", line 41, in dispatch_request
    resp = meth(*args, **kwargs)
  File "C:\Users\allen\.virtualenvs\·s¼W-wo_VgXtn\lib\site-packages\flask_jwt_extended\view_decorators.py", line 170, in decorator
    return current_app.ensure_sync(fn)(*args, **kwargs)
  File "E:\Smitlea_project\·s¼W\HsinyuOS_test\static\util.py", line 36, in wrapper
    return abort(
  File "C:\Users\allen\.virtualenvs\·s¼W-wo_VgXtn\lib\site-packages\flask_restx\errors.py", line 28, in abort
    flask.abort(code)
  File "C:\Users\allen\.virtualenvs\·s¼W-wo_VgXtn\lib\site-packages\flask\helpers.py", line 284, in abort
    current_app.aborter(code, *args, **kwargs)
  File "C:\Users\allen\.virtualenvs\·s¼W-wo_VgXtn\lib\site-packages\werkzeug\exceptions.py", line 876, in __call__
    raise self.mapping[code](*args, **kwargs)
werkzeug.exceptions.InternalServerError: 500 Internal Server Error: The server encountered an internal error and was unable to complete your request. Either the server is overloaded or there is an error in the application.
2025-07-19 01:54:48,259 [DEBUG] models:377 log_response_time - [97m[GET] /announcements took 0.025 seconds[0m
2025-07-19 01:54:48,261 [INFO] _internal:97 _log - [32m127.0.0.1 - - [19/Jul/2025 01:54:48] "[35m[1mGET /announcements HTTP/1.1[0m" 500 -[0m
2025-07-19 01:55:31,038 [DEBUG] models:377 log_response_time - [97m[GET] /announcements took 0.003 seconds[0m
2025-07-19 01:55:31,042 [INFO] _internal:97 _log - [32m127.0.0.1 - - [19/Jul/2025 01:55:31] "GET /announcements HTTP/1.1" 200 -[0m
2025-07-19 01:55:35,015 [DEBUG] models:377 log_response_time - [97m[POST] /announcements took 0.007 seconds[0m
2025-07-19 01:55:35,016 [INFO] _internal:97 _log - [32m127.0.0.1 - - [19/Jul/2025 01:55:35] "POST /announcements HTTP/1.1" 200 -[0m
2025-07-19 01:55:38,645 [DEBUG] models:377 log_response_time - [97m[GET] /announcements took 0.003 seconds[0m
2025-07-19 01:55:38,646 [INFO] _internal:97 _log - [32m127.0.0.1 - - [19/Jul/2025 01:55:38] "GET /announcements HTTP/1.1" 200 -[0m
2025-07-19 01:57:41,026 [DEBUG] models:377 log_response_time - [97m[GET] /announcements took 0.003 seconds[0m
2025-07-19 01:57:41,027 [INFO] _internal:97 _log - [32m127.0.0.1 - - [19/Jul/2025 01:57:41] "GET /announcements HTTP/1.1" 200 -[0m
2025-07-19 01:57:48,700 [ERROR] util:35 wrapper - [91mAn error occurred: NotFound: 404 Not Found: The requested URL was not found on the server. If you entered the URL manually please check your spelling and try again.[0m
2025-07-19 01:57:48,701 [ERROR] app:875 log_exception - [91mException on /announcements/1 [GET][0m
Traceback (most recent call last):
  File "E:\Smitlea_project\·s¼W\HsinyuOS_test\static\util.py", line 22, in wrapper
    return func(*args, **kwargs)
  File "E:\Smitlea_project\·s¼W\HsinyuOS_test\function\hr.py", line 96, in get
    announcement = Announcement.query.get_or_404(ann_id)
  File "C:\Users\allen\.virtualenvs\·s¼W-wo_VgXtn\lib\site-packages\flask_sqlalchemy\query.py", line 33, in get_or_404
    abort(404, description=description)
  File "C:\Users\allen\.virtualenvs\·s¼W-wo_VgXtn\lib\site-packages\flask\helpers.py", line 284, in abort
    current_app.aborter(code, *args, **kwargs)
  File "C:\Users\allen\.virtualenvs\·s¼W-wo_VgXtn\lib\site-packages\werkzeug\exceptions.py", line 876, in __call__
    raise self.mapping[code](*args, **kwargs)
werkzeug.exceptions.NotFound: 404 Not Found: The requested URL was not found on the server. If you entered the URL manually please check your spelling and try again.

During handling of the above exception, another exception occurred:

Traceback (most recent call last):
  File "C:\Users\allen\.virtualenvs\·s¼W-wo_VgXtn\lib\site-packages\flask\app.py", line 917, in full_dispatch_request
    rv = self.dispatch_request()
  File "C:\Users\allen\.virtualenvs\·s¼W-wo_VgXtn\lib\site-packages\flask\app.py", line 902, in dispatch_request
    return self.ensure_sync(self.view_functions[rule.endpoint])(**view_args)  # type: ignore[no-any-return]
  File "C:\Users\allen\.virtualenvs\·s¼W-wo_VgXtn\lib\site-packages\flask_restx\api.py", line 402, in wrapper
    resp = resource(*args, **kwargs)
  File "C:\Users\allen\.virtualenvs\·s¼W-wo_VgXtn\lib\site-packages\flask\views.py", line 110, in view
    return current_app.ensure_sync(self.dispatch_request)(**kwargs)  # type: ignore[no-any-return]
  File "C:\Users\allen\.virtualenvs\·s¼W-wo_VgXtn\lib\site-packages\flask_restx\resource.py", line 41, in dispatch_request
    resp = meth(*args, **kwargs)
  File "C:\Users\allen\.virtualenvs\·s¼W-wo_VgXtn\lib\site-packages\flask_jwt_extended\view_decorators.py", line 170, in decorator
    return current_app.ensure_sync(fn)(*args, **kwargs)
  File "E:\Smitlea_project\·s¼W\HsinyuOS_test\static\util.py", line 36, in wrapper
    return abort(
  File "C:\Users\allen\.virtualenvs\·s¼W-wo_VgXtn\lib\site-packages\flask_restx\errors.py", line 28, in abort
    flask.abort(code)
  File "C:\Users\allen\.virtualenvs\·s¼W-wo_VgXtn\lib\site-packages\flask\helpers.py", line 284, in abort
    current_app.aborter(code, *args, **kwargs)
  File "C:\Users\allen\.virtualenvs\·s¼W-wo_VgXtn\lib\site-packages\werkzeug\exceptions.py", line 876, in __call__
    raise self.mapping[code](*args, **kwargs)
werkzeug.exceptions.InternalServerError: 500 Internal Server Error: The server encountered an internal error and was unable to complete your request. Either the server is overloaded or there is an error in the application.
2025-07-19 01:57:48,715 [DEBUG] models:377 log_response_time - [97m[GET] /announcements/1 took 0.018 seconds[0m
2025-07-19 01:57:48,717 [INFO] _internal:97 _log - [32m127.0.0.1 - - [19/Jul/2025 01:57:48] "[35m[1mGET /announcements/1 HTTP/1.1[0m" 500 -[0m
2025-07-19 01:57:52,211 [ERROR] util:35 wrapper - [91mAn error occurred: TypeError: Announcement.to_dict() takes 1 positional argument but 2 were given[0m
2025-07-19 01:57:52,212 [ERROR] app:875 log_exception - [91mException on /announcements/2 [GET][0m
Traceback (most recent call last):
  File "E:\Smitlea_project\·s¼W\HsinyuOS_test\static\util.py", line 22, in wrapper
    return func(*args, **kwargs)
  File "E:\Smitlea_project\·s¼W\HsinyuOS_test\function\hr.py", line 97, in get
    return {"status": "0", "result": announcement.to_dict(with_photo)}, 200
TypeError: Announcement.to_dict() takes 1 positional argument but 2 were given

During handling of the above exception, another exception occurred:

Traceback (most recent call last):
  File "C:\Users\allen\.virtualenvs\·s¼W-wo_VgXtn\lib\site-packages\flask\app.py", line 917, in full_dispatch_request
    rv = self.dispatch_request()
  File "C:\Users\allen\.virtualenvs\·s¼W-wo_VgXtn\lib\site-packages\flask\app.py", line 902, in dispatch_request
    return self.ensure_sync(self.view_functions[rule.endpoint])(**view_args)  # type: ignore[no-any-return]
  File "C:\Users\allen\.virtualenvs\·s¼W-wo_VgXtn\lib\site-packages\flask_restx\api.py", line 402, in wrapper
    resp = resource(*args, **kwargs)
  File "C:\Users\allen\.virtualenvs\·s¼W-wo_VgXtn\lib\site-packages\flask\views.py", line 110, in view
    return current_app.ensure_sync(self.dispatch_request)(**kwargs)  # type: ignore[no-any-return]
  File "C:\Users\allen\.virtualenvs\·s¼W-wo_VgXtn\lib\site-packages\flask_restx\resource.py", line 41, in dispatch_request
    resp = meth(*args, **kwargs)
  File "C:\Users\allen\.virtualenvs\·s¼W-wo_VgXtn\lib\site-packages\flask_jwt_extended\view_decorators.py", line 170, in decorator
    return current_app.ensure_sync(fn)(*args, **kwargs)
  File "E:\Smitlea_project\·s¼W\HsinyuOS_test\static\util.py", line 36, in wrapper
    return abort(
  File "C:\Users\allen\.virtualenvs\·s¼W-wo_VgXtn\lib\site-packages\flask_restx\errors.py", line 28, in abort
    flask.abort(code)
  File "C:\Users\allen\.virtualenvs\·s¼W-wo_VgXtn\lib\site-packages\flask\helpers.py", line 284, in abort
    current_app.aborter(code, *args, **kwargs)
  File "C:\Users\allen\.virtualenvs\·s¼W-wo_VgXtn\lib\site-packages\werkzeug\exceptions.py", line 876, in __call__
    raise self.mapping[code](*args, **kwargs)
werkzeug.exceptions.InternalServerError: 500 Internal Server Error: The server encountered an internal error and was unable to complete your request. Either the server is overloaded or there is an error in the application.
2025-07-19 01:57:52,223 [DEBUG] models:377 log_response_time - [97m[GET] /announcements/2 took 0.014 seconds[0m
2025-07-19 01:57:52,225 [INFO] _internal:97 _log - [32m127.0.0.1 - - [19/Jul/2025 01:57:52] "[35m[1mGET /announcements/2 HTTP/1.1[0m" 500 -[0m
2025-07-19 01:59:41,065 [ERROR] util:35 wrapper - [91mAn error occurred: TypeError: Announcement.to_dict() takes 1 positional argument but 2 were given[0m
2025-07-19 01:59:41,066 [ERROR] app:875 log_exception - [91mException on /announcements/2 [GET][0m
Traceback (most recent call last):
  File "E:\Smitlea_project\·s¼W\HsinyuOS_test\static\util.py", line 22, in wrapper
    return func(*args, **kwargs)
  File "E:\Smitlea_project\·s¼W\HsinyuOS_test\function\hr.py", line 97, in get
    return {"status": "0", "result": announcement.to_dict(with_photo)}, 200
TypeError: Announcement.to_dict() takes 1 positional argument but 2 were given

During handling of the above exception, another exception occurred:

Traceback (most recent call last):
  File "C:\Users\allen\.virtualenvs\·s¼W-wo_VgXtn\lib\site-packages\flask\app.py", line 917, in full_dispatch_request
    rv = self.dispatch_request()
  File "C:\Users\allen\.virtualenvs\·s¼W-wo_VgXtn\lib\site-packages\flask\app.py", line 902, in dispatch_request
    return self.ensure_sync(self.view_functions[rule.endpoint])(**view_args)  # type: ignore[no-any-return]
  File "C:\Users\allen\.virtualenvs\·s¼W-wo_VgXtn\lib\site-packages\flask_restx\api.py", line 402, in wrapper
    resp = resource(*args, **kwargs)
  File "C:\Users\allen\.virtualenvs\·s¼W-wo_VgXtn\lib\site-packages\flask\views.py", line 110, in view
    return current_app.ensure_sync(self.dispatch_request)(**kwargs)  # type: ignore[no-any-return]
  File "C:\Users\allen\.virtualenvs\·s¼W-wo_VgXtn\lib\site-packages\flask_restx\resource.py", line 41, in dispatch_request
    resp = meth(*args, **kwargs)
  File "C:\Users\allen\.virtualenvs\·s¼W-wo_VgXtn\lib\site-packages\flask_jwt_extended\view_decorators.py", line 170, in decorator
    return current_app.ensure_sync(fn)(*args, **kwargs)
  File "E:\Smitlea_project\·s¼W\HsinyuOS_test\static\util.py", line 36, in wrapper
    return abort(
  File "C:\Users\allen\.virtualenvs\·s¼W-wo_VgXtn\lib\site-packages\flask_restx\errors.py", line 28, in abort
    flask.abort(code)
  File "C:\Users\allen\.virtualenvs\·s¼W-wo_VgXtn\lib\site-packages\flask\helpers.py", line 284, in abort
    current_app.aborter(code, *args, **kwargs)
  File "C:\Users\allen\.virtualenvs\·s¼W-wo_VgXtn\lib\site-packages\werkzeug\exceptions.py", line 876, in __call__
    raise self.mapping[code](*args, **kwargs)
werkzeug.exceptions.InternalServerError: 500 Internal Server Error: The server encountered an internal error and was unable to complete your request. Either the server is overloaded or there is an error in the application.
2025-07-19 01:59:41,076 [DEBUG] models:377 log_response_time - [97m[GET] /announcements/2 took 0.020 seconds[0m
2025-07-19 01:59:41,077 [INFO] _internal:97 _log - [32m127.0.0.1 - - [19/Jul/2025 01:59:41] "[35m[1mGET /announcements/2 HTTP/1.1[0m" 500 -[0m
2025-07-19 01:59:45,253 [INFO] app:100 <module> - [32mDB ¦¨¥\±Ò°Ê[0m
2025-07-19 01:59:46,232 [INFO] _internal:97 _log - [32m[31m[1mWARNING: This is a development server. Do not use it in a production deployment. Use a production WSGI server instead.[0m
 * Running on all addresses (0.0.0.0)
 * Running on http://127.0.0.1:5050
 * Running on http://192.168.1.192:5050[0m
2025-07-19 01:59:46,234 [INFO] _internal:97 _log - [32m[33mPress CTRL+C to quit[0m[0m
2025-07-19 01:59:47,562 [ERROR] util:35 wrapper - [91mAn error occurred: OperationalError: (MySQLdb.OperationalError) (1054, "Unknown column 'announcements.is_deleted' in 'SELECT'")
[SQL: SELECT announcements.title AS announcements_title, announcements.content AS announcements_content, announcements.has_photo AS announcements_has_photo, announcements.record_date AS announcements_record_date, announcements.photo AS announcements_photo, announcements.latitude AS announcements_latitude, announcements.longitude AS announcements_longitude, announcements.created_by AS announcements_created_by, announcements.updated_by AS announcements_updated_by, announcements.is_deleted AS announcements_is_deleted, announcements.id AS announcements_id, announcements.created_at AS announcements_created_at, announcements.updated_at AS announcements_updated_at 
FROM announcements 
WHERE announcements.id = %s]
[parameters: (2,)]
(Background on this error at: https://sqlalche.me/e/20/e3q8)[0m
2025-07-19 01:59:47,565 [ERROR] app:875 log_exception - [91mException on /announcements/2 [GET][0m
Traceback (most recent call last):
  File "C:\Users\allen\.virtualenvs\·s¼W-wo_VgXtn\lib\site-packages\sqlalchemy\engine\base.py", line 1964, in _exec_single_context
    self.dialect.do_execute(
  File "C:\Users\allen\.virtualenvs\·s¼W-wo_VgXtn\lib\site-packages\sqlalchemy\engine\default.py", line 942, in do_execute
    cursor.execute(statement, parameters)
  File "C:\Users\allen\.virtualenvs\·s¼W-wo_VgXtn\lib\site-packages\MySQLdb\cursors.py", line 179, in execute
    res = self._query(mogrified_query)
  File "C:\Users\allen\.virtualenvs\·s¼W-wo_VgXtn\lib\site-packages\MySQLdb\cursors.py", line 330, in _query
    db.query(q)
  File "C:\Users\allen\.virtualenvs\·s¼W-wo_VgXtn\lib\site-packages\MySQLdb\connections.py", line 280, in query
    _mysql.connection.query(self, query)
MySQLdb.OperationalError: (1054, "Unknown column 'announcements.is_deleted' in 'SELECT'")

The above exception was the direct cause of the following exception:

Traceback (most recent call last):
  File "E:\Smitlea_project\·s¼W\HsinyuOS_test\static\util.py", line 22, in wrapper
    return func(*args, **kwargs)
  File "E:\Smitlea_project\·s¼W\HsinyuOS_test\function\hr.py", line 96, in get
    announcement = Announcement.query.get_or_404(ann_id)
  File "C:\Users\allen\.virtualenvs\·s¼W-wo_VgXtn\lib\site-packages\flask_sqlalchemy\query.py", line 30, in get_or_404
    rv = self.get(ident)
  File "<string>", line 2, in get
  File "C:\Users\allen\.virtualenvs\·s¼W-wo_VgXtn\lib\site-packages\sqlalchemy\util\deprecations.py", line 386, in warned
    return fn(*args, **kwargs)  # type: ignore[no-any-return]
  File "C:\Users\allen\.virtualenvs\·s¼W-wo_VgXtn\lib\site-packages\sqlalchemy\orm\query.py", line 1121, in get
    return self._get_impl(ident, loading.load_on_pk_identity)
  File "C:\Users\allen\.virtualenvs\·s¼W-wo_VgXtn\lib\site-packages\sqlalchemy\orm\query.py", line 1130, in _get_impl
    return self.session._get_impl(
  File "C:\Users\allen\.virtualenvs\·s¼W-wo_VgXtn\lib\site-packages\sqlalchemy\orm\session.py", line 3874, in _get_impl
    return db_load_fn(
  File "C:\Users\allen\.virtualenvs\·s¼W-wo_VgXtn\lib\site-packages\sqlalchemy\orm\loading.py", line 694, in load_on_pk_identity
    session.execute(
  File "C:\Users\allen\.virtualenvs\·s¼W-wo_VgXtn\lib\site-packages\sqlalchemy\orm\session.py", line 2365, in execute
    return self._execute_internal(
  File "C:\Users\allen\.virtualenvs\·s¼W-wo_VgXtn\lib\site-packages\sqlalchemy\orm\session.py", line 2251, in _execute_internal
    result: Result[Any] = compile_state_cls.orm_execute_statement(
  File "C:\Users\allen\.virtualenvs\·s¼W-wo_VgXtn\lib\site-packages\sqlalchemy\orm\context.py", line 305, in orm_execute_statement
    result = conn.execute(
  File "C:\Users\allen\.virtualenvs\·s¼W-wo_VgXtn\lib\site-packages\sqlalchemy\engine\base.py", line 1416, in execute
    return meth(
  File "C:\Users\allen\.virtualenvs\·s¼W-wo_VgXtn\lib\site-packages\sqlalchemy\sql\elements.py", line 515, in _execute_on_connection
    return connection._execute_clauseelement(
  File "C:\Users\allen\.virtualenvs\·s¼W-wo_VgXtn\lib\site-packages\sqlalchemy\engine\base.py", line 1638, in _execute_clauseelement
    ret = self._execute_context(
  File "C:\Users\allen\.virtualenvs\·s¼W-wo_VgXtn\lib\site-packages\sqlalchemy\engine\base.py", line 1843, in _execute_context
    return self._exec_single_context(
  File "C:\Users\allen\.virtualenvs\·s¼W-wo_VgXtn\lib\site-packages\sqlalchemy\engine\base.py", line 1983, in _exec_single_context
    self._handle_dbapi_exception(
  File "C:\Users\allen\.virtualenvs\·s¼W-wo_VgXtn\lib\site-packages\sqlalchemy\engine\base.py", line 2352, in _handle_dbapi_exception
    raise sqlalchemy_exception.with_traceback(exc_info[2]) from e
  File "C:\Users\allen\.virtualenvs\·s¼W-wo_VgXtn\lib\site-packages\sqlalchemy\engine\base.py", line 1964, in _exec_single_context
    self.dialect.do_execute(
  File "C:\Users\allen\.virtualenvs\·s¼W-wo_VgXtn\lib\site-packages\sqlalchemy\engine\default.py", line 942, in do_execute
    cursor.execute(statement, parameters)
  File "C:\Users\allen\.virtualenvs\·s¼W-wo_VgXtn\lib\site-packages\MySQLdb\cursors.py", line 179, in execute
    res = self._query(mogrified_query)
  File "C:\Users\allen\.virtualenvs\·s¼W-wo_VgXtn\lib\site-packages\MySQLdb\cursors.py", line 330, in _query
    db.query(q)
  File "C:\Users\allen\.virtualenvs\·s¼W-wo_VgXtn\lib\site-packages\MySQLdb\connections.py", line 280, in query
    _mysql.connection.query(self, query)
sqlalchemy.exc.OperationalError: (MySQLdb.OperationalError) (1054, "Unknown column 'announcements.is_deleted' in 'SELECT'")
[SQL: SELECT announcements.title AS announcements_title, announcements.content AS announcements_content, announcements.has_photo AS announcements_has_photo, announcements.record_date AS announcements_record_date, announcements.photo AS announcements_photo, announcements.latitude AS announcements_latitude, announcements.longitude AS announcements_longitude, announcements.created_by AS announcements_created_by, announcements.updated_by AS announcements_updated_by, announcements.is_deleted AS announcements_is_deleted, announcements.id AS announcements_id, announcements.created_at AS announcements_created_at, announcements.updated_at AS announcements_updated_at 
FROM announcements 
WHERE announcements.id = %s]
[parameters: (2,)]
(Background on this error at: https://sqlalche.me/e/20/e3q8)

During handling of the above exception, another exception occurred:

Traceback (most recent call last):
  File "C:\Users\allen\.virtualenvs\·s¼W-wo_VgXtn\lib\site-packages\flask\app.py", line 917, in full_dispatch_request
    rv = self.dispatch_request()
  File "C:\Users\allen\.virtualenvs\·s¼W-wo_VgXtn\lib\site-packages\flask\app.py", line 902, in dispatch_request
    return self.ensure_sync(self.view_functions[rule.endpoint])(**view_args)  # type: ignore[no-any-return]
  File "C:\Users\allen\.virtualenvs\·s¼W-wo_VgXtn\lib\site-packages\flask_restx\api.py", line 402, in wrapper
    resp = resource(*args, **kwargs)
  File "C:\Users\allen\.virtualenvs\·s¼W-wo_VgXtn\lib\site-packages\flask\views.py", line 110, in view
    return current_app.ensure_sync(self.dispatch_request)(**kwargs)  # type: ignore[no-any-return]
  File "C:\Users\allen\.virtualenvs\·s¼W-wo_VgXtn\lib\site-packages\flask_restx\resource.py", line 41, in dispatch_request
    resp = meth(*args, **kwargs)
  File "C:\Users\allen\.virtualenvs\·s¼W-wo_VgXtn\lib\site-packages\flask_jwt_extended\view_decorators.py", line 170, in decorator
    return current_app.ensure_sync(fn)(*args, **kwargs)
  File "E:\Smitlea_project\·s¼W\HsinyuOS_test\static\util.py", line 36, in wrapper
    return abort(
  File "C:\Users\allen\.virtualenvs\·s¼W-wo_VgXtn\lib\site-packages\flask_restx\errors.py", line 28, in abort
    flask.abort(code)
  File "C:\Users\allen\.virtualenvs\·s¼W-wo_VgXtn\lib\site-packages\flask\helpers.py", line 284, in abort
    current_app.aborter(code, *args, **kwargs)
  File "C:\Users\allen\.virtualenvs\·s¼W-wo_VgXtn\lib\site-packages\werkzeug\exceptions.py", line 876, in __call__
    raise self.mapping[code](*args, **kwargs)
werkzeug.exceptions.InternalServerError: 500 Internal Server Error: The server encountered an internal error and was unable to complete your request. Either the server is overloaded or there is an error in the application.
2025-07-19 01:59:47,652 [DEBUG] models:377 log_response_time - [97m[GET] /announcements/2 took 0.095 seconds[0m
2025-07-19 01:59:47,654 [INFO] _internal:97 _log - [32m127.0.0.1 - - [19/Jul/2025 01:59:47] "[35m[1mGET /announcements/2 HTTP/1.1[0m" 500 -[0m
2025-07-19 02:00:45,578 [INFO] app:100 <module> - [32mDB ¦¨¥\±Ò°Ê[0m
2025-07-19 02:00:46,549 [INFO] _internal:97 _log - [32m[31m[1mWARNING: This is a development server. Do not use it in a production deployment. Use a production WSGI server instead.[0m
 * Running on all addresses (0.0.0.0)
 * Running on http://127.0.0.1:5050
 * Running on http://192.168.1.192:5050[0m
2025-07-19 02:00:46,551 [INFO] _internal:97 _log - [32m[33mPress CTRL+C to quit[0m[0m
2025-07-19 02:00:55,651 [DEBUG] models:377 log_response_time - [97m[GET] /announcements/2 took 0.000 seconds[0m
2025-07-19 02:00:55,653 [INFO] _internal:97 _log - [32m127.0.0.1 - - [19/Jul/2025 02:00:55] "[31m[1mGET /announcements/2 HTTP/1.1[0m" 401 -[0m
2025-07-19 02:01:01,676 [DEBUG] models:377 log_response_time - [97m[POST] /api/login took 0.230 seconds[0m
2025-07-19 02:01:01,678 [INFO] _internal:97 _log - [32m127.0.0.1 - - [19/Jul/2025 02:01:01] "POST /api/login HTTP/1.1" 200 -[0m
2025-07-19 02:08:49,682 [INFO] app:100 <module> - [32mDB ¦¨¥\±Ò°Ê[0m
2025-07-19 02:08:50,654 [INFO] _internal:97 _log - [32m[31m[1mWARNING: This is a development server. Do not use it in a production deployment. Use a production WSGI server instead.[0m
 * Running on all addresses (0.0.0.0)
 * Running on http://127.0.0.1:5050
 * Running on http://192.168.1.192:5050[0m
2025-07-19 02:08:50,655 [INFO] _internal:97 _log - [32m[33mPress CTRL+C to quit[0m[0m
2025-07-19 02:08:52,926 [DEBUG] models:377 log_response_time - [97m[GET] /announcements took 0.000 seconds[0m
2025-07-19 02:08:52,927 [INFO] _internal:97 _log - [32m127.0.0.1 - - [19/Jul/2025 02:08:52] "[31m[1mGET /announcements HTTP/1.1[0m" 401 -[0m
2025-07-19 02:08:56,891 [DEBUG] models:377 log_response_time - [97m[POST] /api/login took 0.189 seconds[0m
2025-07-19 02:08:56,893 [INFO] _internal:97 _log - [32m127.0.0.1 - - [19/Jul/2025 02:08:56] "POST /api/login HTTP/1.1" 200 -[0m
2025-07-19 02:09:02,981 [DEBUG] models:377 log_response_time - [97m[GET] /announcements/2 took 0.000 seconds[0m
2025-07-19 02:09:02,982 [INFO] _internal:97 _log - [32m127.0.0.1 - - [19/Jul/2025 02:09:02] "[31m[1mGET /announcements/2 HTTP/1.1[0m" 401 -[0m
2025-07-19 02:09:11,451 [DEBUG] models:377 log_response_time - [97m[GET] /announcements/2 took 0.003 seconds[0m
2025-07-19 02:09:11,453 [INFO] _internal:97 _log - [32m127.0.0.1 - - [19/Jul/2025 02:09:11] "GET /announcements/2 HTTP/1.1" 200 -[0m
2025-07-19 02:10:55,263 [ERROR] util:35 wrapper - [91mAn error occurred: ProgrammingError: (MySQLdb.ProgrammingError) (1064, "You have an error in your SQL syntax; check the manual that corresponds to your MariaDB server version for the right syntax to use near '), updated_by=1, updated_at='2025-07-19 02:10:55.261236' WHERE announcements....' at line 1")
[SQL: UPDATE announcements SET content=%s, photo=%s, updated_by=%s, updated_at=%s WHERE announcements.id = %s]
[parameters: ('½Ð¤Å§ó·s', [], 1, datetime.datetime(2025, 7, 19, 2, 10, 55, 261236, tzinfo=<DstTzInfo 'Asia/Taipei' CST+8:00:00 STD>), 2)]
(Background on this error at: https://sqlalche.me/e/20/f405)[0m
2025-07-19 02:10:55,264 [ERROR] app:875 log_exception - [91mException on /announcements/2 [PUT][0m
Traceback (most recent call last):
  File "C:\Users\allen\.virtualenvs\·s¼W-wo_VgXtn\lib\site-packages\sqlalchemy\engine\base.py", line 1964, in _exec_single_context
    self.dialect.do_execute(
  File "C:\Users\allen\.virtualenvs\·s¼W-wo_VgXtn\lib\site-packages\sqlalchemy\engine\default.py", line 942, in do_execute
    cursor.execute(statement, parameters)
  File "C:\Users\allen\.virtualenvs\·s¼W-wo_VgXtn\lib\site-packages\MySQLdb\cursors.py", line 179, in execute
    res = self._query(mogrified_query)
  File "C:\Users\allen\.virtualenvs\·s¼W-wo_VgXtn\lib\site-packages\MySQLdb\cursors.py", line 330, in _query
    db.query(q)
  File "C:\Users\allen\.virtualenvs\·s¼W-wo_VgXtn\lib\site-packages\MySQLdb\connections.py", line 280, in query
    _mysql.connection.query(self, query)
MySQLdb.ProgrammingError: (1064, "You have an error in your SQL syntax; check the manual that corresponds to your MariaDB server version for the right syntax to use near '), updated_by=1, updated_at='2025-07-19 02:10:55.261236' WHERE announcements....' at line 1")

The above exception was the direct cause of the following exception:

Traceback (most recent call last):
  File "E:\Smitlea_project\·s¼W\HsinyuOS_test\static\util.py", line 22, in wrapper
    return func(*args, **kwargs)
  File "E:\Smitlea_project\·s¼W\HsinyuOS_test\function\hr.py", line 113, in put
    db.session.commit()
  File "C:\Users\allen\.virtualenvs\·s¼W-wo_VgXtn\lib\site-packages\sqlalchemy\orm\scoping.py", line 599, in commit
    return self._proxied.commit()
  File "C:\Users\allen\.virtualenvs\·s¼W-wo_VgXtn\lib\site-packages\sqlalchemy\orm\session.py", line 2032, in commit
    trans.commit(_to_root=True)
  File "<string>", line 2, in commit
  File "C:\Users\allen\.virtualenvs\·s¼W-wo_VgXtn\lib\site-packages\sqlalchemy\orm\state_changes.py", line 139, in _go
    ret_value = fn(self, *arg, **kw)
  File "C:\Users\allen\.virtualenvs\·s¼W-wo_VgXtn\lib\site-packages\sqlalchemy\orm\session.py", line 1313, in commit
    self._prepare_impl()
  File "<string>", line 2, in _prepare_impl
  File "C:\Users\allen\.virtualenvs\·s¼W-wo_VgXtn\lib\site-packages\sqlalchemy\orm\state_changes.py", line 139, in _go
    ret_value = fn(self, *arg, **kw)
  File "C:\Users\allen\.virtualenvs\·s¼W-wo_VgXtn\lib\site-packages\sqlalchemy\orm\session.py", line 1288, in _prepare_impl
    self.session.flush()
  File "C:\Users\allen\.virtualenvs\·s¼W-wo_VgXtn\lib\site-packages\sqlalchemy\orm\session.py", line 4353, in flush
    self._flush(objects)
  File "C:\Users\allen\.virtualenvs\·s¼W-wo_VgXtn\lib\site-packages\sqlalchemy\orm\session.py", line 4488, in _flush
    with util.safe_reraise():
  File "C:\Users\allen\.virtualenvs\·s¼W-wo_VgXtn\lib\site-packages\sqlalchemy\util\langhelpers.py", line 146, in __exit__
    raise exc_value.with_traceback(exc_tb)
  File "C:\Users\allen\.virtualenvs\·s¼W-wo_VgXtn\lib\site-packages\sqlalchemy\orm\session.py", line 4449, in _flush
    flush_context.execute()
  File "C:\Users\allen\.virtualenvs\·s¼W-wo_VgXtn\lib\site-packages\sqlalchemy\orm\unitofwork.py", line 466, in execute
    rec.execute(self)
  File "C:\Users\allen\.virtualenvs\·s¼W-wo_VgXtn\lib\site-packages\sqlalchemy\orm\unitofwork.py", line 642, in execute
    util.preloaded.orm_persistence.save_obj(
  File "C:\Users\allen\.virtualenvs\·s¼W-wo_VgXtn\lib\site-packages\sqlalchemy\orm\persistence.py", line 85, in save_obj
    _emit_update_statements(
  File "C:\Users\allen\.virtualenvs\·s¼W-wo_VgXtn\lib\site-packages\sqlalchemy\orm\persistence.py", line 912, in _emit_update_statements
    c = connection.execute(
  File "C:\Users\allen\.virtualenvs\·s¼W-wo_VgXtn\lib\site-packages\sqlalchemy\engine\base.py", line 1416, in execute
    return meth(
  File "C:\Users\allen\.virtualenvs\·s¼W-wo_VgXtn\lib\site-packages\sqlalchemy\sql\elements.py", line 515, in _execute_on_connection
    return connection._execute_clauseelement(
  File "C:\Users\allen\.virtualenvs\·s¼W-wo_VgXtn\lib\site-packages\sqlalchemy\engine\base.py", line 1638, in _execute_clauseelement
    ret = self._execute_context(
  File "C:\Users\allen\.virtualenvs\·s¼W-wo_VgXtn\lib\site-packages\sqlalchemy\engine\base.py", line 1843, in _execute_context
    return self._exec_single_context(
  File "C:\Users\allen\.virtualenvs\·s¼W-wo_VgXtn\lib\site-packages\sqlalchemy\engine\base.py", line 1983, in _exec_single_context
    self._handle_dbapi_exception(
  File "C:\Users\allen\.virtualenvs\·s¼W-wo_VgXtn\lib\site-packages\sqlalchemy\engine\base.py", line 2352, in _handle_dbapi_exception
    raise sqlalchemy_exception.with_traceback(exc_info[2]) from e
  File "C:\Users\allen\.virtualenvs\·s¼W-wo_VgXtn\lib\site-packages\sqlalchemy\engine\base.py", line 1964, in _exec_single_context
    self.dialect.do_execute(
  File "C:\Users\allen\.virtualenvs\·s¼W-wo_VgXtn\lib\site-packages\sqlalchemy\engine\default.py", line 942, in do_execute
    cursor.execute(statement, parameters)
  File "C:\Users\allen\.virtualenvs\·s¼W-wo_VgXtn\lib\site-packages\MySQLdb\cursors.py", line 179, in execute
    res = self._query(mogrified_query)
  File "C:\Users\allen\.virtualenvs\·s¼W-wo_VgXtn\lib\site-packages\MySQLdb\cursors.py", line 330, in _query
    db.query(q)
  File "C:\Users\allen\.virtualenvs\·s¼W-wo_VgXtn\lib\site-packages\MySQLdb\connections.py", line 280, in query
    _mysql.connection.query(self, query)
sqlalchemy.exc.ProgrammingError: (MySQLdb.ProgrammingError) (1064, "You have an error in your SQL syntax; check the manual that corresponds to your MariaDB server version for the right syntax to use near '), updated_by=1, updated_at='2025-07-19 02:10:55.261236' WHERE announcements....' at line 1")
[SQL: UPDATE announcements SET content=%s, photo=%s, updated_by=%s, updated_at=%s WHERE announcements.id = %s]
[parameters: ('½Ð¤Å§ó·s', [], 1, datetime.datetime(2025, 7, 19, 2, 10, 55, 261236, tzinfo=<DstTzInfo 'Asia/Taipei' CST+8:00:00 STD>), 2)]
(Background on this error at: https://sqlalche.me/e/20/f405)

During handling of the above exception, another exception occurred:

Traceback (most recent call last):
  File "C:\Users\allen\.virtualenvs\·s¼W-wo_VgXtn\lib\site-packages\flask\app.py", line 917, in full_dispatch_request
    rv = self.dispatch_request()
  File "C:\Users\allen\.virtualenvs\·s¼W-wo_VgXtn\lib\site-packages\flask\app.py", line 902, in dispatch_request
    return self.ensure_sync(self.view_functions[rule.endpoint])(**view_args)  # type: ignore[no-any-return]
  File "C:\Users\allen\.virtualenvs\·s¼W-wo_VgXtn\lib\site-packages\flask_restx\api.py", line 402, in wrapper
    resp = resource(*args, **kwargs)
  File "C:\Users\allen\.virtualenvs\·s¼W-wo_VgXtn\lib\site-packages\flask\views.py", line 110, in view
    return current_app.ensure_sync(self.dispatch_request)(**kwargs)  # type: ignore[no-any-return]
  File "C:\Users\allen\.virtualenvs\·s¼W-wo_VgXtn\lib\site-packages\flask_restx\resource.py", line 41, in dispatch_request
    resp = meth(*args, **kwargs)
  File "C:\Users\allen\.virtualenvs\·s¼W-wo_VgXtn\lib\site-packages\flask_jwt_extended\view_decorators.py", line 170, in decorator
    return current_app.ensure_sync(fn)(*args, **kwargs)
  File "E:\Smitlea_project\·s¼W\HsinyuOS_test\static\util.py", line 36, in wrapper
    return abort(
  File "C:\Users\allen\.virtualenvs\·s¼W-wo_VgXtn\lib\site-packages\flask_restx\errors.py", line 28, in abort
    flask.abort(code)
  File "C:\Users\allen\.virtualenvs\·s¼W-wo_VgXtn\lib\site-packages\flask\helpers.py", line 284, in abort
    current_app.aborter(code, *args, **kwargs)
  File "C:\Users\allen\.virtualenvs\·s¼W-wo_VgXtn\lib\site-packages\werkzeug\exceptions.py", line 876, in __call__
    raise self.mapping[code](*args, **kwargs)
werkzeug.exceptions.InternalServerError: 500 Internal Server Error: The server encountered an internal error and was unable to complete your request. Either the server is overloaded or there is an error in the application.
2025-07-19 02:10:55,322 [DEBUG] models:377 log_response_time - [97m[PUT] /announcements/2 took 0.067 seconds[0m
2025-07-19 02:10:55,324 [INFO] _internal:97 _log - [32m127.0.0.1 - - [19/Jul/2025 02:10:55] "[35m[1mPUT /announcements/2 HTTP/1.1[0m" 500 -[0m
2025-07-19 02:11:15,183 [INFO] app:100 <module> - [32mDB ¦¨¥\±Ò°Ê[0m
2025-07-19 02:11:16,155 [INFO] _internal:97 _log - [32m[31m[1mWARNING: This is a development server. Do not use it in a production deployment. Use a production WSGI server instead.[0m
 * Running on all addresses (0.0.0.0)
 * Running on http://127.0.0.1:5050
 * Running on http://192.168.1.192:5050[0m
2025-07-19 02:11:16,156 [INFO] _internal:97 _log - [32m[33mPress CTRL+C to quit[0m[0m
2025-07-19 02:11:18,274 [ERROR] util:35 wrapper - [91mAn error occurred: ProgrammingError: (MySQLdb.ProgrammingError) (1064, "You have an error in your SQL syntax; check the manual that corresponds to your MariaDB server version for the right syntax to use near '), updated_by=1, updated_at='2025-07-19 02:11:18.274515' WHERE announcements....' at line 1")
[SQL: UPDATE announcements SET content=%s, photo=%s, updated_by=%s, updated_at=%s WHERE announcements.id = %s]
[parameters: ('½Ð¤Å§ó·s', [], 1, datetime.datetime(2025, 7, 19, 2, 11, 18, 274515, tzinfo=<DstTzInfo 'Asia/Taipei' CST+8:00:00 STD>), 2)]
(Background on this error at: https://sqlalche.me/e/20/f405)[0m
2025-07-19 02:11:18,276 [ERROR] app:875 log_exception - [91mException on /announcements/2 [PUT][0m
Traceback (most recent call last):
  File "C:\Users\allen\.virtualenvs\·s¼W-wo_VgXtn\lib\site-packages\sqlalchemy\engine\base.py", line 1964, in _exec_single_context
    self.dialect.do_execute(
  File "C:\Users\allen\.virtualenvs\·s¼W-wo_VgXtn\lib\site-packages\sqlalchemy\engine\default.py", line 942, in do_execute
    cursor.execute(statement, parameters)
  File "C:\Users\allen\.virtualenvs\·s¼W-wo_VgXtn\lib\site-packages\MySQLdb\cursors.py", line 179, in execute
    res = self._query(mogrified_query)
  File "C:\Users\allen\.virtualenvs\·s¼W-wo_VgXtn\lib\site-packages\MySQLdb\cursors.py", line 330, in _query
    db.query(q)
  File "C:\Users\allen\.virtualenvs\·s¼W-wo_VgXtn\lib\site-packages\MySQLdb\connections.py", line 280, in query
    _mysql.connection.query(self, query)
MySQLdb.ProgrammingError: (1064, "You have an error in your SQL syntax; check the manual that corresponds to your MariaDB server version for the right syntax to use near '), updated_by=1, updated_at='2025-07-19 02:11:18.274515' WHERE announcements....' at line 1")

The above exception was the direct cause of the following exception:

Traceback (most recent call last):
  File "E:\Smitlea_project\·s¼W\HsinyuOS_test\static\util.py", line 22, in wrapper
    return func(*args, **kwargs)
  File "E:\Smitlea_project\·s¼W\HsinyuOS_test\function\hr.py", line 113, in put
    db.session.commit()
  File "C:\Users\allen\.virtualenvs\·s¼W-wo_VgXtn\lib\site-packages\sqlalchemy\orm\scoping.py", line 599, in commit
    return self._proxied.commit()
  File "C:\Users\allen\.virtualenvs\·s¼W-wo_VgXtn\lib\site-packages\sqlalchemy\orm\session.py", line 2032, in commit
    trans.commit(_to_root=True)
  File "<string>", line 2, in commit
  File "C:\Users\allen\.virtualenvs\·s¼W-wo_VgXtn\lib\site-packages\sqlalchemy\orm\state_changes.py", line 139, in _go
    ret_value = fn(self, *arg, **kw)
  File "C:\Users\allen\.virtualenvs\·s¼W-wo_VgXtn\lib\site-packages\sqlalchemy\orm\session.py", line 1313, in commit
    self._prepare_impl()
  File "<string>", line 2, in _prepare_impl
  File "C:\Users\allen\.virtualenvs\·s¼W-wo_VgXtn\lib\site-packages\sqlalchemy\orm\state_changes.py", line 139, in _go
    ret_value = fn(self, *arg, **kw)
  File "C:\Users\allen\.virtualenvs\·s¼W-wo_VgXtn\lib\site-packages\sqlalchemy\orm\session.py", line 1288, in _prepare_impl
    self.session.flush()
  File "C:\Users\allen\.virtualenvs\·s¼W-wo_VgXtn\lib\site-packages\sqlalchemy\orm\session.py", line 4353, in flush
    self._flush(objects)
  File "C:\Users\allen\.virtualenvs\·s¼W-wo_VgXtn\lib\site-packages\sqlalchemy\orm\session.py", line 4488, in _flush
    with util.safe_reraise():
  File "C:\Users\allen\.virtualenvs\·s¼W-wo_VgXtn\lib\site-packages\sqlalchemy\util\langhelpers.py", line 146, in __exit__
    raise exc_value.with_traceback(exc_tb)
  File "C:\Users\allen\.virtualenvs\·s¼W-wo_VgXtn\lib\site-packages\sqlalchemy\orm\session.py", line 4449, in _flush
    flush_context.execute()
  File "C:\Users\allen\.virtualenvs\·s¼W-wo_VgXtn\lib\site-packages\sqlalchemy\orm\unitofwork.py", line 466, in execute
    rec.execute(self)
  File "C:\Users\allen\.virtualenvs\·s¼W-wo_VgXtn\lib\site-packages\sqlalchemy\orm\unitofwork.py", line 642, in execute
    util.preloaded.orm_persistence.save_obj(
  File "C:\Users\allen\.virtualenvs\·s¼W-wo_VgXtn\lib\site-packages\sqlalchemy\orm\persistence.py", line 85, in save_obj
    _emit_update_statements(
  File "C:\Users\allen\.virtualenvs\·s¼W-wo_VgXtn\lib\site-packages\sqlalchemy\orm\persistence.py", line 912, in _emit_update_statements
    c = connection.execute(
  File "C:\Users\allen\.virtualenvs\·s¼W-wo_VgXtn\lib\site-packages\sqlalchemy\engine\base.py", line 1416, in execute
    return meth(
  File "C:\Users\allen\.virtualenvs\·s¼W-wo_VgXtn\lib\site-packages\sqlalchemy\sql\elements.py", line 515, in _execute_on_connection
    return connection._execute_clauseelement(
  File "C:\Users\allen\.virtualenvs\·s¼W-wo_VgXtn\lib\site-packages\sqlalchemy\engine\base.py", line 1638, in _execute_clauseelement
    ret = self._execute_context(
  File "C:\Users\allen\.virtualenvs\·s¼W-wo_VgXtn\lib\site-packages\sqlalchemy\engine\base.py", line 1843, in _execute_context
    return self._exec_single_context(
  File "C:\Users\allen\.virtualenvs\·s¼W-wo_VgXtn\lib\site-packages\sqlalchemy\engine\base.py", line 1983, in _exec_single_context
    self._handle_dbapi_exception(
  File "C:\Users\allen\.virtualenvs\·s¼W-wo_VgXtn\lib\site-packages\sqlalchemy\engine\base.py", line 2352, in _handle_dbapi_exception
    raise sqlalchemy_exception.with_traceback(exc_info[2]) from e
  File "C:\Users\allen\.virtualenvs\·s¼W-wo_VgXtn\lib\site-packages\sqlalchemy\engine\base.py", line 1964, in _exec_single_context
    self.dialect.do_execute(
  File "C:\Users\allen\.virtualenvs\·s¼W-wo_VgXtn\lib\site-packages\sqlalchemy\engine\default.py", line 942, in do_execute
    cursor.execute(statement, parameters)
  File "C:\Users\allen\.virtualenvs\·s¼W-wo_VgXtn\lib\site-packages\MySQLdb\cursors.py", line 179, in execute
    res = self._query(mogrified_query)
  File "C:\Users\allen\.virtualenvs\·s¼W-wo_VgXtn\lib\site-packages\MySQLdb\cursors.py", line 330, in _query
    db.query(q)
  File "C:\Users\allen\.virtualenvs\·s¼W-wo_VgXtn\lib\site-packages\MySQLdb\connections.py", line 280, in query
    _mysql.connection.query(self, query)
sqlalchemy.exc.ProgrammingError: (MySQLdb.ProgrammingError) (1064, "You have an error in your SQL syntax; check the manual that corresponds to your MariaDB server version for the right syntax to use near '), updated_by=1, updated_at='2025-07-19 02:11:18.274515' WHERE announcements....' at line 1")
[SQL: UPDATE announcements SET content=%s, photo=%s, updated_by=%s, updated_at=%s WHERE announcements.id = %s]
[parameters: ('½Ð¤Å§ó·s', [], 1, datetime.datetime(2025, 7, 19, 2, 11, 18, 274515, tzinfo=<DstTzInfo 'Asia/Taipei' CST+8:00:00 STD>), 2)]
(Background on this error at: https://sqlalche.me/e/20/f405)

During handling of the above exception, another exception occurred:

Traceback (most recent call last):
  File "C:\Users\allen\.virtualenvs\·s¼W-wo_VgXtn\lib\site-packages\flask\app.py", line 917, in full_dispatch_request
    rv = self.dispatch_request()
  File "C:\Users\allen\.virtualenvs\·s¼W-wo_VgXtn\lib\site-packages\flask\app.py", line 902, in dispatch_request
    return self.ensure_sync(self.view_functions[rule.endpoint])(**view_args)  # type: ignore[no-any-return]
  File "C:\Users\allen\.virtualenvs\·s¼W-wo_VgXtn\lib\site-packages\flask_restx\api.py", line 402, in wrapper
    resp = resource(*args, **kwargs)
  File "C:\Users\allen\.virtualenvs\·s¼W-wo_VgXtn\lib\site-packages\flask\views.py", line 110, in view
    return current_app.ensure_sync(self.dispatch_request)(**kwargs)  # type: ignore[no-any-return]
  File "C:\Users\allen\.virtualenvs\·s¼W-wo_VgXtn\lib\site-packages\flask_restx\resource.py", line 41, in dispatch_request
    resp = meth(*args, **kwargs)
  File "C:\Users\allen\.virtualenvs\·s¼W-wo_VgXtn\lib\site-packages\flask_jwt_extended\view_decorators.py", line 170, in decorator
    return current_app.ensure_sync(fn)(*args, **kwargs)
  File "E:\Smitlea_project\·s¼W\HsinyuOS_test\static\util.py", line 36, in wrapper
    return abort(
  File "C:\Users\allen\.virtualenvs\·s¼W-wo_VgXtn\lib\site-packages\flask_restx\errors.py", line 28, in abort
    flask.abort(code)
  File "C:\Users\allen\.virtualenvs\·s¼W-wo_VgXtn\lib\site-packages\flask\helpers.py", line 284, in abort
    current_app.aborter(code, *args, **kwargs)
  File "C:\Users\allen\.virtualenvs\·s¼W-wo_VgXtn\lib\site-packages\werkzeug\exceptions.py", line 876, in __call__
    raise self.mapping[code](*args, **kwargs)
werkzeug.exceptions.InternalServerError: 500 Internal Server Error: The server encountered an internal error and was unable to complete your request. Either the server is overloaded or there is an error in the application.
2025-07-19 02:11:18,298 [DEBUG] models:377 log_response_time - [97m[PUT] /announcements/2 took 0.031 seconds[0m
2025-07-19 02:11:18,299 [INFO] _internal:97 _log - [32m127.0.0.1 - - [19/Jul/2025 02:11:18] "[35m[1mPUT /announcements/2 HTTP/1.1[0m" 500 -[0m
2025-07-19 02:20:29,947 [INFO] app:100 <module> - [32mDB ¦¨¥\±Ò°Ê[0m
2025-07-19 02:20:30,913 [INFO] _internal:97 _log - [32m[31m[1mWARNING: This is a development server. Do not use it in a production deployment. Use a production WSGI server instead.[0m
 * Running on all addresses (0.0.0.0)
 * Running on http://127.0.0.1:5050
 * Running on http://192.168.1.192:5050[0m
2025-07-19 02:20:30,914 [INFO] _internal:97 _log - [32m[33mPress CTRL+C to quit[0m[0m
2025-07-19 02:20:35,621 [ERROR] util:35 wrapper - [91mAn error occurred: ProgrammingError: (MySQLdb.ProgrammingError) (1064, "You have an error in your SQL syntax; check the manual that corresponds to your MariaDB server version for the right syntax to use near '), updated_by=1, updated_at='2025-07-19 02:20:35.619118' WHERE announcements....' at line 1")
[SQL: UPDATE announcements SET content=%s, photo=%s, updated_by=%s, updated_at=%s WHERE announcements.id = %s]
[parameters: ('½Ð¤Å§ó·s', [], 1, datetime.datetime(2025, 7, 19, 2, 20, 35, 619118, tzinfo=<DstTzInfo 'Asia/Taipei' CST+8:00:00 STD>), 2)]
(Background on this error at: https://sqlalche.me/e/20/f405)[0m
2025-07-19 02:20:35,622 [ERROR] app:875 log_exception - [91mException on /announcements/2 [PUT][0m
Traceback (most recent call last):
  File "C:\Users\allen\.virtualenvs\·s¼W-wo_VgXtn\lib\site-packages\sqlalchemy\engine\base.py", line 1964, in _exec_single_context
    self.dialect.do_execute(
  File "C:\Users\allen\.virtualenvs\·s¼W-wo_VgXtn\lib\site-packages\sqlalchemy\engine\default.py", line 942, in do_execute
    cursor.execute(statement, parameters)
  File "C:\Users\allen\.virtualenvs\·s¼W-wo_VgXtn\lib\site-packages\MySQLdb\cursors.py", line 179, in execute
    res = self._query(mogrified_query)
  File "C:\Users\allen\.virtualenvs\·s¼W-wo_VgXtn\lib\site-packages\MySQLdb\cursors.py", line 330, in _query
    db.query(q)
  File "C:\Users\allen\.virtualenvs\·s¼W-wo_VgXtn\lib\site-packages\MySQLdb\connections.py", line 280, in query
    _mysql.connection.query(self, query)
MySQLdb.ProgrammingError: (1064, "You have an error in your SQL syntax; check the manual that corresponds to your MariaDB server version for the right syntax to use near '), updated_by=1, updated_at='2025-07-19 02:20:35.619118' WHERE announcements....' at line 1")

The above exception was the direct cause of the following exception:

Traceback (most recent call last):
  File "E:\Smitlea_project\·s¼W\HsinyuOS_test\static\util.py", line 22, in wrapper
    return func(*args, **kwargs)
  File "E:\Smitlea_project\·s¼W\HsinyuOS_test\function\hr.py", line 127, in put
    db.session.commit()
  File "C:\Users\allen\.virtualenvs\·s¼W-wo_VgXtn\lib\site-packages\sqlalchemy\orm\scoping.py", line 599, in commit
    return self._proxied.commit()
  File "C:\Users\allen\.virtualenvs\·s¼W-wo_VgXtn\lib\site-packages\sqlalchemy\orm\session.py", line 2032, in commit
    trans.commit(_to_root=True)
  File "<string>", line 2, in commit
  File "C:\Users\allen\.virtualenvs\·s¼W-wo_VgXtn\lib\site-packages\sqlalchemy\orm\state_changes.py", line 139, in _go
    ret_value = fn(self, *arg, **kw)
  File "C:\Users\allen\.virtualenvs\·s¼W-wo_VgXtn\lib\site-packages\sqlalchemy\orm\session.py", line 1313, in commit
    self._prepare_impl()
  File "<string>", line 2, in _prepare_impl
  File "C:\Users\allen\.virtualenvs\·s¼W-wo_VgXtn\lib\site-packages\sqlalchemy\orm\state_changes.py", line 139, in _go
    ret_value = fn(self, *arg, **kw)
  File "C:\Users\allen\.virtualenvs\·s¼W-wo_VgXtn\lib\site-packages\sqlalchemy\orm\session.py", line 1288, in _prepare_impl
    self.session.flush()
  File "C:\Users\allen\.virtualenvs\·s¼W-wo_VgXtn\lib\site-packages\sqlalchemy\orm\session.py", line 4353, in flush
    self._flush(objects)
  File "C:\Users\allen\.virtualenvs\·s¼W-wo_VgXtn\lib\site-packages\sqlalchemy\orm\session.py", line 4488, in _flush
    with util.safe_reraise():
  File "C:\Users\allen\.virtualenvs\·s¼W-wo_VgXtn\lib\site-packages\sqlalchemy\util\langhelpers.py", line 146, in __exit__
    raise exc_value.with_traceback(exc_tb)
  File "C:\Users\allen\.virtualenvs\·s¼W-wo_VgXtn\lib\site-packages\sqlalchemy\orm\session.py", line 4449, in _flush
    flush_context.execute()
  File "C:\Users\allen\.virtualenvs\·s¼W-wo_VgXtn\lib\site-packages\sqlalchemy\orm\unitofwork.py", line 466, in execute
    rec.execute(self)
  File "C:\Users\allen\.virtualenvs\·s¼W-wo_VgXtn\lib\site-packages\sqlalchemy\orm\unitofwork.py", line 642, in execute
    util.preloaded.orm_persistence.save_obj(
  File "C:\Users\allen\.virtualenvs\·s¼W-wo_VgXtn\lib\site-packages\sqlalchemy\orm\persistence.py", line 85, in save_obj
    _emit_update_statements(
  File "C:\Users\allen\.virtualenvs\·s¼W-wo_VgXtn\lib\site-packages\sqlalchemy\orm\persistence.py", line 912, in _emit_update_statements
    c = connection.execute(
  File "C:\Users\allen\.virtualenvs\·s¼W-wo_VgXtn\lib\site-packages\sqlalchemy\engine\base.py", line 1416, in execute
    return meth(
  File "C:\Users\allen\.virtualenvs\·s¼W-wo_VgXtn\lib\site-packages\sqlalchemy\sql\elements.py", line 515, in _execute_on_connection
    return connection._execute_clauseelement(
  File "C:\Users\allen\.virtualenvs\·s¼W-wo_VgXtn\lib\site-packages\sqlalchemy\engine\base.py", line 1638, in _execute_clauseelement
    ret = self._execute_context(
  File "C:\Users\allen\.virtualenvs\·s¼W-wo_VgXtn\lib\site-packages\sqlalchemy\engine\base.py", line 1843, in _execute_context
    return self._exec_single_context(
  File "C:\Users\allen\.virtualenvs\·s¼W-wo_VgXtn\lib\site-packages\sqlalchemy\engine\base.py", line 1983, in _exec_single_context
    self._handle_dbapi_exception(
  File "C:\Users\allen\.virtualenvs\·s¼W-wo_VgXtn\lib\site-packages\sqlalchemy\engine\base.py", line 2352, in _handle_dbapi_exception
    raise sqlalchemy_exception.with_traceback(exc_info[2]) from e
  File "C:\Users\allen\.virtualenvs\·s¼W-wo_VgXtn\lib\site-packages\sqlalchemy\engine\base.py", line 1964, in _exec_single_context
    self.dialect.do_execute(
  File "C:\Users\allen\.virtualenvs\·s¼W-wo_VgXtn\lib\site-packages\sqlalchemy\engine\default.py", line 942, in do_execute
    cursor.execute(statement, parameters)
  File "C:\Users\allen\.virtualenvs\·s¼W-wo_VgXtn\lib\site-packages\MySQLdb\cursors.py", line 179, in execute
    res = self._query(mogrified_query)
  File "C:\Users\allen\.virtualenvs\·s¼W-wo_VgXtn\lib\site-packages\MySQLdb\cursors.py", line 330, in _query
    db.query(q)
  File "C:\Users\allen\.virtualenvs\·s¼W-wo_VgXtn\lib\site-packages\MySQLdb\connections.py", line 280, in query
    _mysql.connection.query(self, query)
sqlalchemy.exc.ProgrammingError: (MySQLdb.ProgrammingError) (1064, "You have an error in your SQL syntax; check the manual that corresponds to your MariaDB server version for the right syntax to use near '), updated_by=1, updated_at='2025-07-19 02:20:35.619118' WHERE announcements....' at line 1")
[SQL: UPDATE announcements SET content=%s, photo=%s, updated_by=%s, updated_at=%s WHERE announcements.id = %s]
[parameters: ('½Ð¤Å§ó·s', [], 1, datetime.datetime(2025, 7, 19, 2, 20, 35, 619118, tzinfo=<DstTzInfo 'Asia/Taipei' CST+8:00:00 STD>), 2)]
(Background on this error at: https://sqlalche.me/e/20/f405)

During handling of the above exception, another exception occurred:

Traceback (most recent call last):
  File "C:\Users\allen\.virtualenvs\·s¼W-wo_VgXtn\lib\site-packages\flask\app.py", line 917, in full_dispatch_request
    rv = self.dispatch_request()
  File "C:\Users\allen\.virtualenvs\·s¼W-wo_VgXtn\lib\site-packages\flask\app.py", line 902, in dispatch_request
    return self.ensure_sync(self.view_functions[rule.endpoint])(**view_args)  # type: ignore[no-any-return]
  File "C:\Users\allen\.virtualenvs\·s¼W-wo_VgXtn\lib\site-packages\flask_restx\api.py", line 402, in wrapper
    resp = resource(*args, **kwargs)
  File "C:\Users\allen\.virtualenvs\·s¼W-wo_VgXtn\lib\site-packages\flask\views.py", line 110, in view
    return current_app.ensure_sync(self.dispatch_request)(**kwargs)  # type: ignore[no-any-return]
  File "C:\Users\allen\.virtualenvs\·s¼W-wo_VgXtn\lib\site-packages\flask_restx\resource.py", line 41, in dispatch_request
    resp = meth(*args, **kwargs)
  File "C:\Users\allen\.virtualenvs\·s¼W-wo_VgXtn\lib\site-packages\flask_jwt_extended\view_decorators.py", line 170, in decorator
    return current_app.ensure_sync(fn)(*args, **kwargs)
  File "E:\Smitlea_project\·s¼W\HsinyuOS_test\static\util.py", line 36, in wrapper
    return abort(
  File "C:\Users\allen\.virtualenvs\·s¼W-wo_VgXtn\lib\site-packages\flask_restx\errors.py", line 28, in abort
    flask.abort(code)
  File "C:\Users\allen\.virtualenvs\·s¼W-wo_VgXtn\lib\site-packages\flask\helpers.py", line 284, in abort
    current_app.aborter(code, *args, **kwargs)
  File "C:\Users\allen\.virtualenvs\·s¼W-wo_VgXtn\lib\site-packages\werkzeug\exceptions.py", line 876, in __call__
    raise self.mapping[code](*args, **kwargs)
werkzeug.exceptions.InternalServerError: 500 Internal Server Error: The server encountered an internal error and was unable to complete your request. Either the server is overloaded or there is an error in the application.
2025-07-19 02:20:35,643 [DEBUG] models:377 log_response_time - [97m[PUT] /announcements/2 took 0.030 seconds[0m
2025-07-19 02:20:35,645 [INFO] _internal:97 _log - [32m127.0.0.1 - - [19/Jul/2025 02:20:35] "[35m[1mPUT /announcements/2 HTTP/1.1[0m" 500 -[0m
2025-07-19 02:24:46,489 [INFO] app:100 <module> - [32mDB ¦¨¥\±Ò°Ê[0m
2025-07-19 02:24:47,464 [INFO] _internal:97 _log - [32m[31m[1mWARNING: This is a development server. Do not use it in a production deployment. Use a production WSGI server instead.[0m
 * Running on all addresses (0.0.0.0)
 * Running on http://127.0.0.1:5050
 * Running on http://192.168.1.192:5050[0m
2025-07-19 02:24:47,465 [INFO] _internal:97 _log - [32m[33mPress CTRL+C to quit[0m[0m
2025-07-19 02:24:51,221 [ERROR] util:35 wrapper - [91mAn error occurred: TypeError: setattr expected 3 arguments, got 2[0m
2025-07-19 02:24:51,222 [ERROR] app:875 log_exception - [91mException on /announcements/2 [PUT][0m
Traceback (most recent call last):
  File "E:\Smitlea_project\·s¼W\HsinyuOS_test\static\util.py", line 22, in wrapper
    return func(*args, **kwargs)
  File "E:\Smitlea_project\·s¼W\HsinyuOS_test\function\hr.py", line 124, in put
    setattr(announcement, field)
TypeError: setattr expected 3 arguments, got 2

During handling of the above exception, another exception occurred:

Traceback (most recent call last):
  File "C:\Users\allen\.virtualenvs\·s¼W-wo_VgXtn\lib\site-packages\flask\app.py", line 917, in full_dispatch_request
    rv = self.dispatch_request()
  File "C:\Users\allen\.virtualenvs\·s¼W-wo_VgXtn\lib\site-packages\flask\app.py", line 902, in dispatch_request
    return self.ensure_sync(self.view_functions[rule.endpoint])(**view_args)  # type: ignore[no-any-return]
  File "C:\Users\allen\.virtualenvs\·s¼W-wo_VgXtn\lib\site-packages\flask_restx\api.py", line 402, in wrapper
    resp = resource(*args, **kwargs)
  File "C:\Users\allen\.virtualenvs\·s¼W-wo_VgXtn\lib\site-packages\flask\views.py", line 110, in view
    return current_app.ensure_sync(self.dispatch_request)(**kwargs)  # type: ignore[no-any-return]
  File "C:\Users\allen\.virtualenvs\·s¼W-wo_VgXtn\lib\site-packages\flask_restx\resource.py", line 41, in dispatch_request
    resp = meth(*args, **kwargs)
  File "C:\Users\allen\.virtualenvs\·s¼W-wo_VgXtn\lib\site-packages\flask_jwt_extended\view_decorators.py", line 170, in decorator
    return current_app.ensure_sync(fn)(*args, **kwargs)
  File "E:\Smitlea_project\·s¼W\HsinyuOS_test\static\util.py", line 36, in wrapper
    return abort(
  File "C:\Users\allen\.virtualenvs\·s¼W-wo_VgXtn\lib\site-packages\flask_restx\errors.py", line 28, in abort
    flask.abort(code)
  File "C:\Users\allen\.virtualenvs\·s¼W-wo_VgXtn\lib\site-packages\flask\helpers.py", line 284, in abort
    current_app.aborter(code, *args, **kwargs)
  File "C:\Users\allen\.virtualenvs\·s¼W-wo_VgXtn\lib\site-packages\werkzeug\exceptions.py", line 876, in __call__
    raise self.mapping[code](*args, **kwargs)
werkzeug.exceptions.InternalServerError: 500 Internal Server Error: The server encountered an internal error and was unable to complete your request. Either the server is overloaded or there is an error in the application.
2025-07-19 02:24:51,230 [DEBUG] models:377 log_response_time - [97m[PUT] /announcements/2 took 0.015 seconds[0m
2025-07-19 02:24:51,231 [INFO] _internal:97 _log - [32m127.0.0.1 - - [19/Jul/2025 02:24:51] "[35m[1mPUT /announcements/2 HTTP/1.1[0m" 500 -[0m
2025-07-19 02:25:23,619 [INFO] app:100 <module> - [32mDB ¦¨¥\±Ò°Ê[0m
2025-07-19 02:25:24,592 [INFO] _internal:97 _log - [32m[31m[1mWARNING: This is a development server. Do not use it in a production deployment. Use a production WSGI server instead.[0m
 * Running on all addresses (0.0.0.0)
 * Running on http://127.0.0.1:5050
 * Running on http://192.168.1.192:5050[0m
2025-07-19 02:25:24,594 [INFO] _internal:97 _log - [32m[33mPress CTRL+C to quit[0m[0m
2025-07-19 02:25:25,773 [ERROR] util:35 wrapper - [91mAn error occurred: TypeError: setattr expected 3 arguments, got 2[0m
2025-07-19 02:25:25,773 [ERROR] app:875 log_exception - [91mException on /announcements/2 [PUT][0m
Traceback (most recent call last):
  File "E:\Smitlea_project\·s¼W\HsinyuOS_test\static\util.py", line 22, in wrapper
    return func(*args, **kwargs)
  File "E:\Smitlea_project\·s¼W\HsinyuOS_test\function\hr.py", line 124, in put
    setattr(announcement, field)
TypeError: setattr expected 3 arguments, got 2

During handling of the above exception, another exception occurred:

Traceback (most recent call last):
  File "C:\Users\allen\.virtualenvs\·s¼W-wo_VgXtn\lib\site-packages\flask\app.py", line 917, in full_dispatch_request
    rv = self.dispatch_request()
  File "C:\Users\allen\.virtualenvs\·s¼W-wo_VgXtn\lib\site-packages\flask\app.py", line 902, in dispatch_request
    return self.ensure_sync(self.view_functions[rule.endpoint])(**view_args)  # type: ignore[no-any-return]
  File "C:\Users\allen\.virtualenvs\·s¼W-wo_VgXtn\lib\site-packages\flask_restx\api.py", line 402, in wrapper
    resp = resource(*args, **kwargs)
  File "C:\Users\allen\.virtualenvs\·s¼W-wo_VgXtn\lib\site-packages\flask\views.py", line 110, in view
    return current_app.ensure_sync(self.dispatch_request)(**kwargs)  # type: ignore[no-any-return]
  File "C:\Users\allen\.virtualenvs\·s¼W-wo_VgXtn\lib\site-packages\flask_restx\resource.py", line 41, in dispatch_request
    resp = meth(*args, **kwargs)
  File "C:\Users\allen\.virtualenvs\·s¼W-wo_VgXtn\lib\site-packages\flask_jwt_extended\view_decorators.py", line 170, in decorator
    return current_app.ensure_sync(fn)(*args, **kwargs)
  File "E:\Smitlea_project\·s¼W\HsinyuOS_test\static\util.py", line 36, in wrapper
    return abort(
  File "C:\Users\allen\.virtualenvs\·s¼W-wo_VgXtn\lib\site-packages\flask_restx\errors.py", line 28, in abort
    flask.abort(code)
  File "C:\Users\allen\.virtualenvs\·s¼W-wo_VgXtn\lib\site-packages\flask\helpers.py", line 284, in abort
    current_app.aborter(code, *args, **kwargs)
  File "C:\Users\allen\.virtualenvs\·s¼W-wo_VgXtn\lib\site-packages\werkzeug\exceptions.py", line 876, in __call__
    raise self.mapping[code](*args, **kwargs)
werkzeug.exceptions.InternalServerError: 500 Internal Server Error: The server encountered an internal error and was unable to complete your request. Either the server is overloaded or there is an error in the application.
2025-07-19 02:25:25,781 [DEBUG] models:377 log_response_time - [97m[PUT] /announcements/2 took 0.014 seconds[0m
2025-07-19 02:25:25,783 [INFO] _internal:97 _log - [32m127.0.0.1 - - [19/Jul/2025 02:25:25] "[35m[1mPUT /announcements/2 HTTP/1.1[0m" 500 -[0m
2025-07-19 02:26:21,173 [INFO] app:100 <module> - [32mDB ¦¨¥\±Ò°Ê[0m
2025-07-19 02:26:22,140 [INFO] _internal:97 _log - [32m[31m[1mWARNING: This is a development server. Do not use it in a production deployment. Use a production WSGI server instead.[0m
 * Running on all addresses (0.0.0.0)
 * Running on http://127.0.0.1:5050
 * Running on http://192.168.1.192:5050[0m
2025-07-19 02:26:22,141 [INFO] _internal:97 _log - [32m[33mPress CTRL+C to quit[0m[0m
2025-07-19 02:26:26,614 [DEBUG] models:377 log_response_time - [97m[PUT] /announcements/2 took 0.013 seconds[0m
2025-07-19 02:26:26,616 [INFO] _internal:97 _log - [32m127.0.0.1 - - [19/Jul/2025 02:26:26] "PUT /announcements/2 HTTP/1.1" 200 -[0m
2025-07-19 02:26:39,022 [DEBUG] models:377 log_response_time - [97m[GET] /announcements took 0.000 seconds[0m
2025-07-19 02:26:39,023 [INFO] _internal:97 _log - [32m127.0.0.1 - - [19/Jul/2025 02:26:39] "[31m[1mGET /announcements HTTP/1.1[0m" 401 -[0m
2025-07-19 02:26:43,151 [DEBUG] models:377 log_response_time - [97m[POST] /api/login took 0.191 seconds[0m
2025-07-19 02:26:43,152 [INFO] _internal:97 _log - [32m127.0.0.1 - - [19/Jul/2025 02:26:43] "POST /api/login HTTP/1.1" 200 -[0m
2025-07-19 02:27:02,488 [DEBUG] models:377 log_response_time - [97m[GET] /announcements took 0.003 seconds[0m
2025-07-19 02:27:02,489 [INFO] _internal:97 _log - [32m127.0.0.1 - - [19/Jul/2025 02:27:02] "GET /announcements HTTP/1.1" 200 -[0m
2025-07-19 02:27:53,726 [DEBUG] models:377 log_response_time - [97m[DELETE] /announcements/2 took 0.001 seconds[0m
2025-07-19 02:27:53,727 [INFO] _internal:97 _log - [32m127.0.0.1 - - [19/Jul/2025 02:27:53] "[31m[1mDELETE /announcements/2 HTTP/1.1[0m" 401 -[0m
2025-07-19 02:28:00,571 [DEBUG] models:377 log_response_time - [97m[POST] /api/login took 0.197 seconds[0m
2025-07-19 02:28:00,574 [INFO] _internal:97 _log - [32m127.0.0.1 - - [19/Jul/2025 02:28:00] "POST /api/login HTTP/1.1" 200 -[0m
2025-07-19 02:28:05,445 [DEBUG] models:377 log_response_time - [97m[DELETE] /announcements/2 took 0.006 seconds[0m
2025-07-19 02:28:05,446 [INFO] _internal:97 _log - [32m127.0.0.1 - - [19/Jul/2025 02:28:05] "DELETE /announcements/2 HTTP/1.1" 200 -[0m
2025-07-19 02:29:14,771 [INFO] app:100 <module> - [32mDB ¦¨¥\±Ò°Ê[0m
2025-07-19 02:29:15,744 [INFO] _internal:97 _log - [32m[31m[1mWARNING: This is a development server. Do not use it in a production deployment. Use a production WSGI server instead.[0m
 * Running on all addresses (0.0.0.0)
 * Running on http://127.0.0.1:5050
 * Running on http://192.168.1.192:5050[0m
2025-07-19 02:29:15,745 [INFO] _internal:97 _log - [32m[33mPress CTRL+C to quit[0m[0m
2025-07-19 02:29:17,909 [DEBUG] models:377 log_response_time - [97m[GET] /leaves took 0.001 seconds[0m
2025-07-19 02:29:17,910 [INFO] _internal:97 _log - [32m127.0.0.1 - - [19/Jul/2025 02:29:17] "[31m[1mGET /leaves HTTP/1.1[0m" 401 -[0m
2025-07-19 02:29:22,340 [DEBUG] models:377 log_response_time - [97m[POST] /api/login took 0.197 seconds[0m
2025-07-19 02:29:22,342 [INFO] _internal:97 _log - [32m127.0.0.1 - - [19/Jul/2025 02:29:22] "POST /api/login HTTP/1.1" 200 -[0m
2025-07-19 02:29:27,036 [DEBUG] models:377 log_response_time - [97m[GET] /leaves took 0.000 seconds[0m
2025-07-19 02:29:27,037 [INFO] _internal:97 _log - [32m127.0.0.1 - - [19/Jul/2025 02:29:27] "[31m[1mGET /leaves HTTP/1.1[0m" 401 -[0m
2025-07-19 02:29:38,402 [DEBUG] models:377 log_response_time - [97m[GET] /leaves took 0.009 seconds[0m
2025-07-19 02:29:38,404 [INFO] _internal:97 _log - [32m127.0.0.1 - - [19/Jul/2025 02:29:38] "GET /leaves HTTP/1.1" 200 -[0m
2025-07-19 02:29:46,283 [DEBUG] models:377 log_response_time - [97m[GET] /leaves took 0.003 seconds[0m
2025-07-19 02:29:46,285 [INFO] _internal:97 _log - [32m127.0.0.1 - - [19/Jul/2025 02:29:46] "GET /leaves HTTP/1.1" 200 -[0m
2025-07-19 02:31:36,239 [DEBUG] models:377 log_response_time - [97m[DELETE] /leaves took 0.001 seconds[0m
2025-07-19 02:31:36,239 [INFO] _internal:97 _log - [32m127.0.0.1 - - [19/Jul/2025 02:31:36] "[31m[1mDELETE /leaves HTTP/1.1[0m" 405 -[0m
2025-07-19 02:34:41,609 [DEBUG] models:377 log_response_time - [97m[GET] /leaves took 0.006 seconds[0m
2025-07-19 02:34:41,610 [INFO] _internal:97 _log - [32m127.0.0.1 - - [19/Jul/2025 02:34:41] "GET /leaves HTTP/1.1" 200 -[0m
2025-07-19 02:35:41,666 [DEBUG] models:377 log_response_time - [97m[POST] /leaves took 0.000 seconds[0m
2025-07-19 02:35:41,667 [INFO] _internal:97 _log - [32m127.0.0.1 - - [19/Jul/2025 02:35:41] "[31m[1mPOST /leaves HTTP/1.1[0m" 401 -[0m
2025-07-19 02:35:46,033 [DEBUG] models:377 log_response_time - [97m[POST] /api/login took 0.189 seconds[0m
2025-07-19 02:35:46,035 [INFO] _internal:97 _log - [32m127.0.0.1 - - [19/Jul/2025 02:35:46] "POST /api/login HTTP/1.1" 200 -[0m
2025-07-19 02:35:52,982 [DEBUG] models:377 log_response_time - [97m[POST] /leaves took 0.006 seconds[0m
2025-07-19 02:35:52,983 [INFO] _internal:97 _log - [32m127.0.0.1 - - [19/Jul/2025 02:35:52] "[35m[1mPOST /leaves HTTP/1.1[0m" 201 -[0m
2025-07-19 02:36:00,018 [DEBUG] models:377 log_response_time - [97m[GET] /leaves took 0.003 seconds[0m
2025-07-19 02:36:00,019 [INFO] _internal:97 _log - [32m127.0.0.1 - - [19/Jul/2025 02:36:00] "GET /leaves HTTP/1.1" 200 -[0m
2025-07-19 02:39:20,776 [DEBUG] models:377 log_response_time - [97m[PUT] /leaves/1/approve took 0.004 seconds[0m
2025-07-19 02:39:20,777 [INFO] _internal:97 _log - [32m127.0.0.1 - - [19/Jul/2025 02:39:20] "[31m[1mPUT /leaves/1/approve HTTP/1.1[0m" 400 -[0m
2025-07-19 02:39:28,448 [DEBUG] models:377 log_response_time - [97m[PUT] /leaves/1/approve took 0.011 seconds[0m
2025-07-19 02:39:28,449 [INFO] _internal:97 _log - [32m127.0.0.1 - - [19/Jul/2025 02:39:28] "PUT /leaves/1/approve HTTP/1.1" 200 -[0m
2025-07-19 02:55:27,629 [DEBUG] models:377 log_response_time - [97m[GET] /sop took 0.010 seconds[0m
2025-07-19 02:55:27,632 [INFO] _internal:97 _log - [32m127.0.0.1 - - [19/Jul/2025 02:55:27] "GET /sop HTTP/1.1" 200 -[0m
2025-07-19 02:55:50,559 [DEBUG] models:377 log_response_time - [97m[GET] /sop took 0.003 seconds[0m
2025-07-19 02:55:50,560 [INFO] _internal:97 _log - [32m127.0.0.1 - - [19/Jul/2025 02:55:50] "GET /sop HTTP/1.1" 200 -[0m
2025-07-19 02:59:31,783 [DEBUG] models:377 log_response_time - [97m[POST] /sop took 0.008 seconds[0m
2025-07-19 02:59:31,784 [INFO] _internal:97 _log - [32m127.0.0.1 - - [19/Jul/2025 02:59:31] "[35m[1mPOST /sop HTTP/1.1[0m" 201 -[0m
2025-07-19 02:59:35,645 [DEBUG] models:377 log_response_time - [97m[GET] /sop took 0.002 seconds[0m
2025-07-19 02:59:35,648 [INFO] _internal:97 _log - [32m127.0.0.1 - - [19/Jul/2025 02:59:35] "GET /sop HTTP/1.1" 200 -[0m
2025-07-19 03:01:14,041 [DEBUG] models:377 log_response_time - [97m[GET] /leaves took 0.007 seconds[0m
2025-07-19 03:01:14,042 [INFO] _internal:97 _log - [32m127.0.0.1 - - [19/Jul/2025 03:01:14] "GET /leaves HTTP/1.1" 200 -[0m
2025-07-19 03:05:08,794 [DEBUG] models:377 log_response_time - [97m[PUT] /sop/1 took 0.008 seconds[0m
2025-07-19 03:05:08,796 [INFO] _internal:97 _log - [32m127.0.0.1 - - [19/Jul/2025 03:05:08] "PUT /sop/1 HTTP/1.1" 200 -[0m
